Workbook

Sheet Standard Estimator - SALES
E1: STEP 1 - is this item in or out of scope: | G1: STEP 2 - for yellow cells only: | Q1: STEP 3 - add assumptions here in client-friendly language:
A2: Phase | B2: Service | C2: Area | D2: Deliverable | E2: Is this deliverable in scope? | F2: Type (variable quantity or fixed) | H2: Enter quantity here | I2: Fixed quantity | J2: Total quantity scoped | K2: Effort per quantity unit (hours) | L2: Total effort scoped for this deliverable (hours) | M2: Rate ($/hr) | N2: Overhead % | O2: Fully Loaded Cost ($) | P2: Min Sell ($) | Q2: Assumptions
A3: FOUNDATIONS | B3: Design | C3: Discovery | D3: Kickoff + stakeholder alignment workshop | E3: NO | F3: FIXED | H3: 10 | I3: =if(F3="FIXED", 1, "") -> 1 | J3: =if((E3="YES"), (if(F3="FIXED", I3, H3)), 0) -> 0 | K3: 3 | L3: =J3*K3 -> 0 | M3: 40 | N3: 0.2 | O3: =IFERROR(J3*K3*M3*(1+N3),0) -> 0 | P3: =O3*2 -> 0
A4: FOUNDATIONS | B4: Design | C4: Discovery | D4: Competitive website review (per competitor) | E4: NO | F4: VARIABLE | G4: Number of competitor websites to be audited: | H4: 2 | I4: =if(F4="FIXED", 1, "") | J4: =if((E4="YES"), (if(F4="FIXED", I4, H4)), 0) -> 0 | K4: 0.75 | L4: =J4*K4 -> 0 | M4: 40 | N4: 0.2 | O4: =IFERROR(J4*K4*M4*(1+N4),0) -> 0 | P4: =O4*2 -> 0
A5: FOUNDATIONS | B5: Design | C5: Discovery | D5: Design inspiration / moodboard sprint | E5: NO | F5: FIXED | I5: =if(F5="FIXED", 1, "") -> 1 | J5: =if((E5="YES"), (if(F5="FIXED", I5, H5)), 0) -> 0 | K5: 2 | L5: =J5*K5 -> 0 | M5: 40 | N5: 0.2 | O5: =IFERROR(J5*K5*M5*(1+N5),0) -> 0 | P5: =O5*2 -> 0
A6: FOUNDATIONS | B6: Design | C6: Branding | D6: Brand audit (current guidelines + assets) | E6: NO | F6: FIXED | I6: =if(F6="FIXED", 1, "") -> 1 | J6: =if((E6="YES"), (if(F6="FIXED", I6, H6)), 0) -> 0 | K6: 3 | L6: =J6*K6 -> 0 | M6: 40 | N6: 0.2 | O6: =IFERROR(J6*K6*M6*(1+N6),0) -> 0 | P6: =O6*2 -> 0
A7: DESIGN | B7: Design | C7: Branding | D7: Logo refinement (light) | E7: NO | F7: FIXED | I7: =if(F7="FIXED", 1, "") -> 1 | J7: =if((E7="YES"), (if(F7="FIXED", I7, H7)), 0) -> 0 | K7: 6 | L7: =J7*K7 -> 0 | M7: 40 | N7: 0.2 | O7: =IFERROR(J7*K7*M7*(1+N7),0) -> 0 | P7: =O7*2 -> 0
A8: DESIGN | B8: Design | C8: Branding | D8: Logo redesign (full) | E8: NO | F8: FIXED | I8: =if(F8="FIXED", 1, "") -> 1 | J8: =if((E8="YES"), (if(F8="FIXED", I8, H8)), 0) -> 0 | K8: 12 | L8: =J8*K8 -> 0 | M8: 40 | N8: 0.2 | O8: =IFERROR(J8*K8*M8*(1+N8),0) -> 0 | P8: =O8*2 -> 0
A9: DESIGN | B9: Design | C9: Branding | D9: Color palette system | E9: NO | F9: FIXED | I9: =if(F9="FIXED", 1, "") -> 1 | J9: =if((E9="YES"), (if(F9="FIXED", I9, H9)), 0) -> 0 | K9: 2 | L9: =J9*K9 -> 0 | M9: 40 | N9: 0.2 | O9: =IFERROR(J9*K9*M9*(1+N9),0) -> 0 | P9: =O9*2 -> 0
A10: DESIGN | B10: Design | C10: Branding | D10: Typography system | E10: NO | F10: FIXED | I10: =if(F10="FIXED", 1, "") -> 1 | J10: =if((E10="YES"), (if(F10="FIXED", I10, H10)), 0) -> 0 | K10: 2 | L10: =J10*K10 -> 0 | M10: 40 | N10: 0.2 | O10: =IFERROR(J10*K10*M10*(1+N10),0) -> 0 | P10: =O10*2 -> 0
A11: DESIGN | B11: Design | C11: Branding | D11: Iconography style + starter set (10 icons) | E11: NO | F11: FIXED | I11: =if(F11="FIXED", 1, "") -> 1 | J11: =if((E11="YES"), (if(F11="FIXED", I11, H11)), 0) -> 0 | K11: 4 | L11: =J11*K11 -> 0 | M11: 40 | N11: 0.2 | O11: =IFERROR(J11*K11*M11*(1+N11),0) -> 0 | P11: =O11*2 -> 0
A12: DESIGN | B12: Design | C12: Branding | D12: Illustration style definition | E12: NO | F12: FIXED | I12: =if(F12="FIXED", 1, "") -> 1 | J12: =if((E12="YES"), (if(F12="FIXED", I12, H12)), 0) -> 0 | K12: 3 | L12: =J12*K12 -> 0 | M12: 40 | N12: 0.2 | O12: =IFERROR(J12*K12*M12*(1+N12),0) -> 0 | P12: =O12*2 -> 0
A13: DESIGN | B13: Design | C13: Branding | D13: Brand guidelines (lite – 10–15 pages) | E13: NO | F13: FIXED | I13: =if(F13="FIXED", 1, "") -> 1 | J13: =if((E13="YES"), (if(F13="FIXED", I13, H13)), 0) -> 0 | K13: 8 | L13: =J13*K13 -> 0 | M13: 40 | N13: 0.2 | O13: =IFERROR(J13*K13*M13*(1+N13),0) -> 0 | P13: =O13*2 -> 0
A14: FOUNDATIONS | B14: Design | C14: UX | D14: Information architecture + sitemap | E14: NO | F14: FIXED | I14: =if(F14="FIXED", 1, "") -> 1 | J14: =if((E14="YES"), (if(F14="FIXED", I14, H14)), 0) -> 0 | K14: 4 | L14: =J14*K14 -> 0 | M14: 40 | N14: 0.2 | O14: =IFERROR(J14*K14*M14*(1+N14),0) -> 0 | P14: =O14*2 -> 0
A15: FOUNDATIONS | B15: Design | C15: UX | D15: Wireframes – homepage | E15: NO | F15: FIXED | I15: =if(F15="FIXED", 1, "") -> 1 | J15: =if((E15="YES"), (if(F15="FIXED", I15, H15)), 0) -> 0 | K15: 4 | L15: =J15*K15 -> 0 | M15: 40 | N15: 0.2 | O15: =IFERROR(J15*K15*M15*(1+N15),0) -> 0 | P15: =O15*2 -> 0 | R15: NO
A16: FOUNDATIONS | B16: Design | C16: UX | D16: Wireframes – template page type (per template) | E16: NO | F16: VARIABLE | G16: Number of templates we are assuming: | H16: 10 | I16: =if(F16="FIXED", 1, "") | J16: =if((E16="YES"), (if(F16="FIXED", I16, H16)), 0) -> 0 | K16: 2.5 | L16: =J16*K16 -> 0 | M16: 40 | N16: 0.2 | O16: =IFERROR(J16*K16*M16*(1+N16),0) -> 0 | P16: =O16*2 -> 0
A17: FOUNDATIONS | B17: Design | C17: UX | D17: Form UX (contact/demo) wireframe | E17: NO | F17: FIXED | I17: =if(F17="FIXED", 1, "") -> 1 | J17: =if((E17="YES"), (if(F17="FIXED", I17, H17)), 0) -> 0 | K17: 1.5 | L17: =J17*K17 -> 0 | M17: 40 | N17: 0.2 | O17: =IFERROR(J17*K17*M17*(1+N17),0) -> 0 | P17: =O17*2 -> 0
A18: FOUNDATIONS | B18: Design | C18: UX | D18: Pricing UX wireframe | E18: NO | F18: FIXED | I18: =if(F18="FIXED", 1, "") -> 1 | J18: =if((E18="YES"), (if(F18="FIXED", I18, H18)), 0) -> 0 | K18: 2 | L18: =J18*K18 -> 0 | M18: 40 | N18: 0.2 | O18: =IFERROR(J18*K18*M18*(1+N18),0) -> 0 | P18: =O18*2 -> 0
A19: DESIGN | B19: Design | C19: UI System | D19: Figma project setup + page grid | E19: NO | F19: FIXED | I19: =if(F19="FIXED", 1, "") -> 1 | J19: =if((E19="YES"), (if(F19="FIXED", I19, H19)), 0) -> 0 | K19: 1 | L19: =J19*K19 -> 0 | M19: 40 | N19: 0.2 | O19: =IFERROR(J19*K19*M19*(1+N19),0) -> 0 | P19: =O19*2 -> 0
A20: DESIGN | B20: Design | C20: UI System | D20: UI kit: typography styles | E20: NO | F20: FIXED | I20: =if(F20="FIXED", 1, "") -> 1 | J20: =if((E20="YES"), (if(F20="FIXED", I20, H20)), 0) -> 0 | K20: 1.5 | L20: =J20*K20 -> 0 | M20: 40 | N20: 0.2 | O20: =IFERROR(J20*K20*M20*(1+N20),0) -> 0 | P20: =O20*2 -> 0
A21: DESIGN | B21: Design | C21: UI System | D21: UI kit: color tokens + semantic roles | E21: NO | F21: FIXED | I21: =if(F21="FIXED", 1, "") -> 1 | J21: =if((E21="YES"), (if(F21="FIXED", I21, H21)), 0) -> 0 | K21: 1.5 | L21: =J21*K21 -> 0 | M21: 40 | N21: 0.2 | O21: =IFERROR(J21*K21*M21*(1+N21),0) -> 0 | P21: =O21*2 -> 0
A22: DESIGN | B22: Design | C22: UI System | D22: UI kit: spacing scale + layout primitives | E22: NO | F22: FIXED | I22: =if(F22="FIXED", 1, "") -> 1 | J22: =if((E22="YES"), (if(F22="FIXED", I22, H22)), 0) -> 0 | K22: 1.5 | L22: =J22*K22 -> 0 | M22: 40 | N22: 0.2 | O22: =IFERROR(J22*K22*M22*(1+N22),0) -> 0 | P22: =O22*2 -> 0
A23: DESIGN | B23: Design | C23: UI System | D23: Component design: buttons (states) | E23: NO | F23: FIXED | I23: =if(F23="FIXED", 1, "") -> 1 | J23: =if((E23="YES"), (if(F23="FIXED", I23, H23)), 0) -> 0 | K23: 1.5 | L23: =J23*K23 -> 0 | M23: 40 | N23: 0.2 | O23: =IFERROR(J23*K23*M23*(1+N23),0) -> 0 | P23: =O23*2 -> 0
A24: DESIGN | B24: Design | C24: UI System | D24: Component design: forms (inputs, selects, errors) | E24: NO | F24: FIXED | I24: =if(F24="FIXED", 1, "") -> 1 | J24: =if((E24="YES"), (if(F24="FIXED", I24, H24)), 0) -> 0 | K24: 2 | L24: =J24*K24 -> 0 | M24: 40 | N24: 0.2 | O24: =IFERROR(J24*K24*M24*(1+N24),0) -> 0 | P24: =O24*2 -> 0
A25: DESIGN | B25: Design | C25: UI System | D25: Component design: cards (variants) | E25: NO | F25: FIXED | I25: =if(F25="FIXED", 1, "") -> 1 | J25: =if((E25="YES"), (if(F25="FIXED", I25, H25)), 0) -> 0 | K25: 2 | L25: =J25*K25 -> 0 | M25: 40 | N25: 0.2 | O25: =IFERROR(J25*K25*M25*(1+N25),0) -> 0 | P25: =O25*2 -> 0
A26: DESIGN | B26: Design | C26: UI System | D26: Component design: accordions + tabs | E26: NO | F26: FIXED | I26: =if(F26="FIXED", 1, "") -> 1 | J26: =if((E26="YES"), (if(F26="FIXED", I26, H26)), 0) -> 0 | K26: 2 | L26: =J26*K26 -> 0 | M26: 40 | N26: 0.2 | O26: =IFERROR(J26*K26*M26*(1+N26),0) -> 0 | P26: =O26*2 -> 0
A27: DESIGN | B27: Design | C27: UI System | D27: Component design: sliders/carousels | E27: NO | F27: FIXED | I27: =if(F27="FIXED", 1, "") -> 1 | J27: =if((E27="YES"), (if(F27="FIXED", I27, H27)), 0) -> 0 | K27: 2 | L27: =J27*K27 -> 0 | M27: 40 | N27: 0.2 | O27: =IFERROR(J27*K27*M27*(1+N27),0) -> 0 | P27: =O27*2 -> 0
A28: DESIGN | B28: Design | C28: UI System | D28: Component design: pricing table | E28: NO | F28: FIXED | I28: =if(F28="FIXED", 1, "") -> 1 | J28: =if((E28="YES"), (if(F28="FIXED", I28, H28)), 0) -> 0 | K28: 2.5 | L28: =J28*K28 -> 0 | M28: 40 | N28: 0.2 | O28: =IFERROR(J28*K28*M28*(1+N28),0) -> 0 | P28: =O28*2 -> 0
... A54: DESIGN | B54: Design | C54: Page UI | D54: 404 page UI design | E54: NO | F54: FIXED | I54: =if(F54="FIXED", 1, "") -> 1 | J54: =if((E54="YES"), (if(F54="FIXED", I54, H54)), 0) -> 0 | K54: 1.5 | L54: =J54*K54 -> 0 | M54: 40 | N54: 0.2 | O54: =IFERROR(J54*K54*M54*(1+N54),0) -> 0 | P54: =O54*2 -> 0
A55: DESIGN | B55: Design | C55: Graphics | D55: Hero illustration / composite (per page) | E55: NO | F55: VARIABLE | G55: Number of pages needing hero illustration / composite: | I55: =if(F55="FIXED", 1, "") | J55: =if((E55="YES"), (if(F55="FIXED", I55, H55)), 0) -> 0 | K55: 3 | L55: =J55*K55 -> 0 | M55: 40 | N55: 0.2 | O55: =IFERROR(J55*K55*M55*(1+N55),0) -> 0 | P55: =O55*2 -> 0
A56: DESIGN | B56: Design | C56: Graphics | D56: Product UI mockup (per screenshot) | E56: NO | F56: VARIABLE | G56: Number of product UI mock up screenshots needed: | I56: =if(F56="FIXED", 1, "") | J56: =if((E56="YES"), (if(F56="FIXED", I56, H56)), 0) -> 0 | K56: 0.75 | L56: =J56*K56 -> 0 | M56: 40 | N56: 0.2 | O56: =IFERROR(J56*K56*M56*(1+N56),0) -> 0 | P56: =O56*2 -> 0
A57: DESIGN | B57: Design | C57: Graphics | D57: Feature diagram (per diagram) | E57: NO | F57: VARIABLE | G57: Number of feature diagrams: | I57: =if(F57="FIXED", 1, "") | J57: =if((E57="YES"), (if(F57="FIXED", I57, H57)), 0) -> 0 | K57: 1.5 | L57: =J57*K57 -> 0 | M57: 40 | N57: 0.2 | O57: =IFERROR(J57*K57*M57*(1+N57),0) -> 0 | P57: =O57*2 -> 0
A58: DESIGN | B58: Design | C58: Graphics | D58: Background pattern / texture | E58: NO | F58: FIXED | I58: =if(F58="FIXED", 1, "") -> 1 | J58: =if((E58="YES"), (if(F58="FIXED", I58, H58)), 0) -> 0 | K58: 1 | L58: =J58*K58 -> 0 | M58: 40 | N58: 0.2 | O58: =IFERROR(J58*K58*M58*(1+N58),0) -> 0 | P58: =O58*2 -> 0
A59: DESIGN | B59: Design | C59: Graphics | D59: Image editing + compositing (per image) | E59: NO | F59: VARIABLE | G59: Number of images assumed for edit/compositing: | I59: =if(F59="FIXED", 1, "") | J59: =if((E59="YES"), (if(F59="FIXED", I59, H59)), 0) -> 0 | K59: 0.5 | L59: =J59*K59 -> 0 | M59: 40 | N59: 0.2 | O59: =IFERROR(J59*K59*M59*(1+N59),0) -> 0 | P59: =O59*2 -> 0
A60: DESIGN | B60: Design | C60: Graphics | D60: Infographic for webpage | E60: NO | F60: FIXED | I60: =if(F60="FIXED", 1, "") -> 1 | J60: =if((E60="YES"), (if(F60="FIXED", I60, H60)), 0) -> 0 | K60: 4 | L60: =J60*K60 -> 0 | M60: 40 | N60: 0.2 | O60: =IFERROR(J60*K60*M60*(1+N60),0) -> 0 | P60: =O60*2 -> 0
A61: DELIVERY | B61: Design | C61: Handoff | D61: Design-dev handoff walkthrough | E61: NO | F61: FIXED | I61: =if(F61="FIXED", 1, "") -> 1 | J61: =if((E61="YES"), (if(F61="FIXED", I61, H61)), 0) -> 0 | K61: 2 | L61: =J61*K61 -> 0 | M61: 40 | N61: 0.2 | O61: =IFERROR(J61*K61*M61*(1+N61),0) -> 0 | P61: =O61*2 -> 0
A62: DESIGN | B62: Design | C62: Handoff | D62: Design QA round (per page) | E62: NO | F62: VARIABLE | G62: Number of pages needing design QA: | I62: =if(F62="FIXED", 1, "") | J62: =if((E62="YES"), (if(F62="FIXED", I62, H62)), 0) -> 0 | K62: 0.75 | L62: =J62*K62 -> 0 | M62: 40 | N62: 0.2 | O62: =IFERROR(J62*K62*M62*(1+N62),0) -> 0 | P62: =O62*2 -> 0
A63: FOUNDATIONS | B63: Dev | C63: Foundation | D63: Webflow project setup + environments | E63: NO | F63: FIXED | I63: =if(F63="FIXED", 1, "") -> 1 | J63: =if((E63="YES"), (if(F63="FIXED", I63, H63)), 0) -> 0 | K63: 2 | L63: =J63*K63 -> 0 | M63: 40 | N63: 0.2 | O63: =IFERROR(J63*K63*M63*(1+N63),0) -> 0 | P63: =O63*2 -> 0
A64: FOUNDATIONS | B64: Dev | C64: Foundation | D64: Domain + DNS coordination (staging) | E64: NO | F64: FIXED | I64: =if(F64="FIXED", 1, "") -> 1 | J64: =if((E64="YES"), (if(F64="FIXED", I64, H64)), 0) -> 0 | K64: 1 | L64: =J64*K64 -> 0 | M64: 40 | N64: 0.2 | O64: =IFERROR(J64*K64*M64*(1+N64),0) -> 0 | P64: =O64*2 -> 0
A65: FOUNDATIONS | B65: Dev | C65: Foundation | D65: Global style guide build (classes, variables) | E65: NO | F65: FIXED | I65: =if(F65="FIXED", 1, "") -> 1 | J65: =if((E65="YES"), (if(F65="FIXED", I65, H65)), 0) -> 0 | K65: 8 | L65: =J65*K65 -> 0 | M65: 40 | N65: 0.2 | O65: =IFERROR(J65*K65*M65*(1+N65),0) -> 0 | P65: =O65*2 -> 0
...

Sheet Output to go into proposal appe
A1: PROPOSAL APPENDIX: Agreed project scope | H1: Use this column to filter for YES once scope is agreed, then copy and paste columns A to F to proposal appendix
A3: Service | B3: Area | C3: Deliverable | F3: Assumptions | H3: Is this deliverable in scope?
A4: ='Standard Estimator - SALES'!B3 -> Design | B4: ='Standard Estimator - SALES'!C3 -> Discovery | C4: ='Standard Estimator - SALES'!D3 -> Kickoff + stakeholder alignment workshop | D4: ='Standard Estimator - SALES'!G3 | E4: =if('Standard Estimator - SALES'!F3="VARIABLE", 'Standard Estimator - SALES'!H3, "") | F4: ='Standard Estimator - SALES'!Q3 | H4: ='Standard Estimator - SALES'!E3 -> NO
A5: ='Standard Estimator - SALES'!B4 -> Design | B5: ='Standard Estimator - SALES'!C4 -> Discovery | C5: ='Standard Estimator - SALES'!D4 -> Competitive website review (per competitor) | D5: ='Standard Estimator - SALES'!G4 -> Number of competitor websites to be audited: | E5: =if('Standard Estimator - SALES'!F4="VARIABLE", 'Standard Estimator - SALES'!H4, "") -> 2 | F5: ='Standard Estimator - SALES'!Q4 | H5: ='Standard Estimator - SALES'!E4 -> NO
A6: ='Standard Estimator - SALES'!B5 -> Design | B6: ='Standard Estimator - SALES'!C5 -> Discovery | C6: ='Standard Estimator - SALES'!D5 -> Design inspiration / moodboard sprint | D6: ='Standard Estimator - SALES'!G5 | E6: =if('Standard Estimator - SALES'!F5="VARIABLE", 'Standard Estimator - SALES'!H5, "") | F6: ='Standard Estimator - SALES'!Q5 | H6: ='Standard Estimator - SALES'!E5 -> NO
A7: ='Standard Estimator - SALES'!B6 -> Design | B7: ='Standard Estimator - SALES'!C6 -> Branding | C7: ='Standard Estimator - SALES'!D6 -> Brand audit (current guidelines + assets) | D7: ='Standard Estimator - SALES'!G6 | E7: =if('Standard Estimator - SALES'!F6="VARIABLE", 'Standard Estimator - SALES'!H6, "") | F7: ='Standard Estimator - SALES'!Q6 | H7: ='Standard Estimator - SALES'!E6 -> NO
A8: ='Standard Estimator - SALES'!B7 -> Design | B8: ='Standard Estimator - SALES'!C7 -> Branding | C8: ='Standard Estimator - SALES'!D7 -> Logo refinement (light) | D8: ='Standard Estimator - SALES'!G7 | E8: =if('Standard Estimator - SALES'!F7="VARIABLE", 'Standard Estimator - SALES'!H7, "") | F8: ='Standard Estimator - SALES'!Q7 | H8: ='Standard Estimator - SALES'!E7 -> NO
A9: ='Standard Estimator - SALES'!B8 -> Design | B9: ='Standard Estimator - SALES'!C8 -> Branding | C9: ='Standard Estimator - SALES'!D8 -> Logo redesign (full) | D9: ='Standard Estimator - SALES'!G8 | E9: =if('Standard Estimator - SALES'!F8="VARIABLE", 'Standard Estimator - SALES'!H8, "") | F9: ='Standard Estimator - SALES'!Q8 | H9: ='Standard Estimator - SALES'!E8 -> NO
A10: ='Standard Estimator - SALES'!B9 -> Design | B10: ='Standard Estimator - SALES'!C9 -> Branding | C10: ='Standard Estimator - SALES'!D9 -> Color palette system | D10: ='Standard Estimator - SALES'!G9 | E10: =if('Standard Estimator - SALES'!F9="VARIABLE", 'Standard Estimator - SALES'!H9, "") | F10: ='Standard Estimator - SALES'!Q9 | H10: ='Standard Estimator - SALES'!E9 -> NO
A11: ='Standard Estimator - SALES'!B10 -> Design | B11: ='Standard Estimator - SALES'!C10 -> Branding | C11: ='Standard Estimator - SALES'!D10 -> Typography system | D11: ='Standard Estimator - SALES'!G10 | E11: =if('Standard Estimator - SALES'!F10="VARIABLE", 'Standard Estimator - SALES'!H10, "") | F11: ='Standard Estimator - SALES'!Q10 | H11: ='Standard Estimator - SALES'!E10 -> NO
A12: ='Standard Estimator - SALES'!B11 -> Design | B12: ='Standard Estimator - SALES'!C11 -> Branding | C12: ='Standard Estimator - SALES'!D11 -> Iconography style + starter set (10 icons) | D12: ='Standard Estimator - SALES'!G11 | E12: =if('Standard Estimator - SALES'!F11="VARIABLE", 'Standard Estimator - SALES'!H11, "") | F12: ='Standard Estimator - SALES'!Q11 | H12: ='Standard Estimator - SALES'!E11 -> NO
A13: ='Standard Estimator - SALES'!B12 -> Design | B13: ='Standard Estimator - SALES'!C12 -> Branding | C13: ='Standard Estimator - SALES'!D12 -> Illustration style definition | D13: ='Standard Estimator - SALES'!G12 | E13: =if('Standard Estimator - SALES'!F12="VARIABLE", 'Standard Estimator - SALES'!H12, "") | F13: ='Standard Estimator - SALES'!Q12 | H13: ='Standard Estimator - SALES'!E12 -> NO
A14: ='Standard Estimator - SALES'!B13 -> Design | B14: ='Standard Estimator - SALES'!C13 -> Branding | C14: ='Standard Estimator - SALES'!D13 -> Brand guidelines (lite – 10–15 pages) | D14: ='Standard Estimator - SALES'!G13 | E14: =if('Standard Estimator - SALES'!F13="VARIABLE", 'Standard Estimator - SALES'!H13, "") | F14: ='Standard Estimator - SALES'!Q13 | H14: ='Standard Estimator - SALES'!E13 -> NO
A15: ='Standard Estimator - SALES'!B14 -> Design | B15: ='Standard Estimator - SALES'!C14 -> UX | C15: ='Standard Estimator - SALES'!D14 -> Information architecture + sitemap | D15: ='Standard Estimator - SALES'!G14 | E15: =if('Standard Estimator - SALES'!F14="VARIABLE", 'Standard Estimator - SALES'!H14, "") | F15: ='Standard Estimator - SALES'!Q14 | H15: ='Standard Estimator - SALES'!E14 -> NO
... A148: ='Standard Estimator - SALES'!B147 -> Growth | B148: ='Standard Estimator - SALES'!C147 -> WAIO | C148: ='Standard Estimator - SALES'!D147 -> WAIO template recommendations (per template) | D148: ='Standard Estimator - SALES'!G147 | E148: =if('Standard Estimator - SALES'!F147="VARIABLE", 'Standard Estimator - SALES'!H147, "") | F148: ='Standard Estimator - SALES'!Q147 | H148: ='Standard Estimator - SALES'!E147 -> NO
E149: =if('Standard Estimator - SALES'!F148="VARIABLE", 'Standard Estimator - SALES'!H148, "") | H149: ='Standard Estimator - SALES'!E148
E150: =if('Standard Estimator - SALES'!F149="VARIABLE", 'Standard Estimator - SALES'!H149, "") | H150: ='Standard Estimator - SALES'!E149
E151: =if('Standard Estimator - SALES'!F150="VARIABLE", 'Standard Estimator - SALES'!H150, "") | H151: ='Standard Estimator - SALES'!E150
E152: =if('Standard Estimator - SALES'!F151="VARIABLE", 'Standard Estimator - SALES'!H151, "") | H152: ='Standard Estimator - SALES'!E151
E153: =if('Standard Estimator - SALES'!F152="VARIABLE", 'Standard Estimator - SALES'!H152, "") | H153: ='Standard Estimator - SALES'!E152
E154: =if('Standard Estimator - SALES'!F153="VARIABLE", 'Standard Estimator - SALES'!H153, "") | H154: ='Standard Estimator - SALES'!E153
E155: =if('Standard Estimator - SALES'!F154="VARIABLE", 'Standard Estimator - SALES'!H154, "") | H155: ='Standard Estimator - SALES'!E154
E156: =if('Standard Estimator - SALES'!F155="VARIABLE", 'Standard Estimator - SALES'!H155, "") | H156: ='Standard Estimator - SALES'!E153
E157: =if('Standard Estimator - SALES'!F156="VARIABLE", 'Standard Estimator - SALES'!H156, "") | H157: ='Standard Estimator - SALES'!E154
E158: =if('Standard Estimator - SALES'!F157="VARIABLE", 'Standard Estimator - SALES'!H157, "") | H158: ='Standard Estimator - SALES'!E155
E159: =if('Standard Estimator - SALES'!F158="VARIABLE", 'Standard Estimator - SALES'!H158, "") | H159: ='Standard Estimator - SALES'!E156
E160: =if('Standard Estimator - SALES'!F159="VARIABLE", 'Standard Estimator - SALES'!H159, "") | H160: ='Standard Estimator - SALES'!E157
E161: =if('Standard Estimator - SALES'!F160="VARIABLE", 'Standard Estimator - SALES'!H160, "") | H161: ='Standard Estimator - SALES'!E158
E162: =if('Standard Estimator - SALES'!F161="VARIABLE", 'Standard Estimator - SALES'!H161, "") | H162: ='Standard Estimator - SALES'!E159
E163: =if('Standard Estimator - SALES'!F162="VARIABLE", 'Standard Estimator - SALES'!H162, "") | H163: ='Standard Estimator - SALES'!E160
E164: =if('Standard Estimator - SALES'!F163="VARIABLE", 'Standard Estimator - SALES'!H163, "") | H164: ='Standard Estimator - SALES'!E161
E165: =if('Standard Estimator - SALES'!F164="VARIABLE", 'Standard Estimator - SALES'!H164, "") | H165: ='Standard Estimator - SALES'!E162
E166: =if('Standard Estimator - SALES'!F165="VARIABLE", 'Standard Estimator - SALES'!H165, "") | H166: ='Standard Estimator - SALES'!E163
E167: =if('Standard Estimator - SALES'!F166="VARIABLE", 'Standard Estimator - SALES'!H166, "") | H167: ='Standard Estimator - SALES'!E164
... E169: =if('Standard Estimator - SALES'!F168="VARIABLE", 'Standard Estimator - SALES'!H168, "") | H169: ='Standard Estimator - SALES'!E166
H170: ='Standard Estimator - SALES'!E167
H171: ='Standard Estimator - SALES'!E168
H172: ='Standard Estimator - SALES'!E169
H173: ='Standard Estimator - SALES'!E170
H174: ='Standard Estimator - SALES'!E171
...

Sheet Project Scope and Pricing Table
B1: EFFORT (hours) | F1: COMMERCIALS ($)
B2: Total effort scoped for deliverables per phase (hours) | C2: 20% allowance for PM/AM (hours) | D2: Total effort (hours) | F2: Minimum charge rate ($) | G2: Minimum cost per phase ($) | H2: Growth lead commercial adjustment ($) | I2: Cost to quote to client ($)
A3: FOUNDATIONS | B3: =SUMIF('Standard Estimator - SALES'!$A$3:$A$147,A3,'Standard Estimator - SALES'!$L$3:$L$147) -> 0 | C3: =B3*0.2 -> 0 | D3: =sum(B3:C3) -> 0 | F3: 40 | G3: =D3*F3 -> 0 | H3: 0 | I3: =G3+H3 -> 0
A4: DESIGN | B4: =SUMIF('Standard Estimator - SALES'!$A$3:$A$147,A4,'Standard Estimator - SALES'!$L$3:$L$147) -> 0 | C4: =B4*0.2 -> 0 | D4: =sum(B4:C4) -> 0 | F4: 40 | G4: =D4*F4 -> 0 | H4: 0 | I4: =G4+H4 -> 0
A5: DELIVERY | B5: =SUMIF('Standard Estimator - SALES'!$A$3:$A$147,A5,'Standard Estimator - SALES'!$L$3:$L$147) -> 0 | C5: =B5*0.2 -> 0 | D5: =sum(B5:C5) -> 0 | F5: 40 | G5: =D5*F5 -> 0 | H5: 0 | I5: =G5+H5 -> 0
A6: LAUNCH | B6: =SUMIF('Standard Estimator - SALES'!$A$3:$A$147,A6,'Standard Estimator - SALES'!$L$3:$L$147) -> 0 | C6: =B6*0.2 -> 0 | D6: =sum(B6:C6) -> 0 | F6: 40 | G6: =D6*F6 -> 0 | H6: 0 | I6: =G6+H6 -> 0
A7: PROJECT TOTAL | B7: =sum(B3:B6) -> 0 | C7: =sum(C3:C6) -> 0 | D7: =sum(D3:D6) -> 0 | F7: =AVERAGE(F3:F6) -> 40 | G7: =sum(G3:G6) -> 0 | H7: =sum(H3:H6) -> 0 | I7: =sum(I3:I6) -> 0
H9: Growth lead can apply discount or increase in the yellow cells to achieve target cost to quote to client.
H11: TO DO: Build out GM% calcs here to get better insight into target/guardrail profitability per project
H12: TO DO: Think about how localisation needs incorporating into Standard Estimator - SALES. Lendo project learning.
